<?xml version="1.0"?>


<robot name="robotiq_85_gripper" xmlns:xacro="http://ros.org/wiki/xacro">
    <xacro:include filename="$(find robotiq_85_description)/urdf/robotiq_85_gripper.transmission.xacro" />
    <property name="pi" value="3.14159"/>
    <property name="K" value="3000"/>
    <xacro:macro name="robotiq_85_gripper" params="prefix parent *origin">

        <link name="${prefix}robotiq_85_coupling">
            <visual>
                <geometry>
                    <mesh filename="package://robotiq_85_description/meshes/visual/gripper_coupling.dae" />
                </geometry>
                <origin rpy="0 0 ${pi}" xyz="0 0 0" />
            </visual>
            <collision>
                <geometry>
                    <mesh filename="package://robotiq_85_description/meshes/collision/gripper_coupling.stl" />
                </geometry>
                <origin rpy="0 0 ${pi}" xyz="0 0 0" />
            </collision>
        </link>

        <joint name="${prefix}gripper_to_flange" type="fixed">
            <parent link="${parent}" />
            <child link="${prefix}robotiq_85_coupling" />
            <xacro:insert_block name="origin" />
        </joint>

        <joint name="${prefix}robotiq_85_base_joint" type="fixed">
            <parent link="${prefix}robotiq_85_coupling"/>
            <child link="${prefix}robotiq_85_base_link"/>
            <origin xyz="0 0 0.00545" rpy="0 -1.570795 0" />
            <xacro:insert_block name="origin"/>
        </joint>

        <!-- gazebo -->
		<gazebo reference="${prefix}robotiq_85_coupling">
			<implicitSpringDamper>1</implicitSpringDamper>
			<mu1>100000</mu1>
			<mu2>100000</mu2>
			<kp>100000000.0</kp>
			<kd>1.0</kd>
  		</gazebo>

        <link name="${prefix}robotiq_85_base_link">
            <visual>
                <geometry>
                    <mesh filename="package://robotiq_85_description/meshes/visual/robotiq_85_base_link.dae"/>
                </geometry>
            </visual>
            <collision>
                <geometry>
                    <mesh filename="package://robotiq_85_description/meshes/collision/robotiq_85_base_link.stl"/>
                </geometry>
            </collision>
            <inertial>
               <mass value="0.0000636951" />
               <origin xyz="0.0 0.0 0.0" />
               <inertia ixx = "${0.000380/K/3}" ixy = "${0.000000/K}" ixz = "${0.000000/K}"
                        iyx = "${0.000000/K}" iyy = "${0.001110/K}" iyz = "${0.000000/K}"
                        izx = "${0.000000/K}" izy = "${0.000000/K}" izz = "${0.001171/K}" />
               </inertial>
        </link>
        <!-- gazebo -->
		<gazebo reference="${prefix}robotiq_85_base_link">
			<implicitSpringDamper>1</implicitSpringDamper>
			<mu1>100000</mu1>
			<mu2>100000</mu2>
			<kp>100000000.0</kp>
			<kd>1.0</kd>
  		</gazebo>
        <joint name="${prefix}robotiq_85_left_knuckle_joint" type="revolute">
            <parent link="${prefix}robotiq_85_base_link"/>
            <child link="${prefix}robotiq_85_left_knuckle_link"/>
            <axis xyz="0 0 1"/>
            <origin rpy="${pi} 0.0 0.0" xyz="0.027452258135 0.015300572215 0.0"/>
            <limit lower="0.0" upper="0.804" velocity="2.0" effort="1000"/>
        </joint>

        <joint name="${prefix}robotiq_85_right_knuckle_joint" type="continuous">
            <parent link="${prefix}robotiq_85_base_link"/>
            <child link="${prefix}robotiq_85_right_knuckle_link"/>
            <axis xyz="0 0 1"/>
            <origin rpy="0.0 0.0 0.0" xyz="0.027452258135 -0.015300572215 0.0"/>
            <limit lower="-3.14" upper="3.14" velocity="100.0" effort="1000"/>
            <mimic joint="${prefix}robotiq_85_left_knuckle_joint"/>
        </joint>

        <link name="${prefix}robotiq_85_left_knuckle_link">
            <visual>
                <geometry>
                    <mesh filename="package://robotiq_85_description/meshes/visual/robotiq_85_knuckle_link.dae"/>
                </geometry>
            </visual>
            <collision>
                <geometry>
                    <mesh filename="package://robotiq_85_description/meshes/collision/robotiq_85_knuckle_link.stl"/>
                </geometry>
            </collision>
            <inertial>
              <mass value="0.0000018491" />
              <origin xyz="0.0 0.0 0.0" />
              <inertia ixx = "${0.000009/K}" ixy = "${-0.000001/K}" ixz = "${0.000000/K}"
                       iyx = "${-0.000001/K}" iyy = "${0.000001/K}" iyz = "${0.000000/K}"
                       izx = "${0.000000/K}" izy = "${0.000000/K}" izz = "${0.000010/K}" />
            </inertial>
        </link> 
        <!-- gazebo -->
		<gazebo reference="${prefix}robotiq_85_left_knuckle_link">
			<implicitSpringDamper>1</implicitSpringDamper>
			<mu1>100000</mu1>
			<mu2>100000</mu2>
			<kp>100000000.0</kp>
			<kd>1.0</kd>
  		</gazebo>
        <link name="${prefix}robotiq_85_right_knuckle_link">
            <visual>
                <geometry>
                    <mesh filename="package://robotiq_85_description/meshes/visual/robotiq_85_knuckle_link.dae"/>
                </geometry>
            </visual>
            <collision>
                <geometry>
                    <mesh filename="package://robotiq_85_description/meshes/collision/robotiq_85_knuckle_link.stl"/>
                </geometry>
            </collision>
            <inertial>
              <mass value="0.0000018491" />
              <origin xyz="0.0 0.0 0.0" />
              <inertia ixx = "${0.000009/K}" ixy = "${-0.000001/K}" ixz = "${0.000000/K}"
                       iyx = "${-0.000001/K}" iyy = "${0.000001/K}" iyz = "${0.000000/K}"
                       izx = "${0.000000/K}" izy = "${0.000000/K}" izz = "${0.000010/K}" />
            </inertial>
        </link>
        <!-- gazebo -->
		<gazebo reference="${prefix}robotiq_85_right_knuckle_link">
			<implicitSpringDamper>1</implicitSpringDamper>
			<mu1>100000</mu1>
			<mu2>100000</mu2>
			<kp>100000000.0</kp>
			<kd>1.0</kd>
  		</gazebo>
        <joint name="${prefix}robotiq_85_left_finger_joint" type="fixed">
            <parent link="${prefix}robotiq_85_left_knuckle_link"/>
            <child link="${prefix}robotiq_85_left_finger_link"/>
            <origin xyz="-0.002042762275 -0.015743022175 0.0" rpy="0 0 0" />
        </joint>

        <joint name="${prefix}robotiq_85_right_finger_joint" type="fixed">
            <parent link="${prefix}robotiq_85_right_knuckle_link"/>
            <child link="${prefix}robotiq_85_right_finger_link"/>
            <origin xyz="-0.002042762275 -0.015743022175 0.0" rpy="0 0 0" />
        </joint>

        <link name="${prefix}robotiq_85_left_finger_link">
            <visual>
                <geometry>
                    <mesh filename="package://robotiq_85_description/meshes/visual/robotiq_85_finger_link.dae"/>
                </geometry>
            </visual>
            <collision>
                <geometry>
                    <mesh filename="package://robotiq_85_description/meshes/collision/robotiq_85_finger_link.stl"/>
                </geometry>
            </collision>
            <inertial>
              <mass value="0.0000027309" />
              <origin xyz="0.0 0.0 0.0" />
              <inertia ixx = "${0.000003/K}" ixy = "${-0.000002/K}" ixz = "${0.000000/K}"
                       iyx = "${-0.000002/K}" iyy = "${0.000021/K}" iyz = "${0.000000/K}"
                       izx = "${0.000000/K}" izy = "${0.000000/K}" izz = "${0.000020/K}" />
            </inertial>
        </link> 
        <!-- gazebo -->
		<gazebo reference="${prefix}robotiq_85_left_finger_link">
			<implicitSpringDamper>1</implicitSpringDamper>
			<mu1>100000</mu1>
			<mu2>100000</mu2>
			<kp>100000000.0</kp>
			<kd>1.0</kd>
  		</gazebo>
        <link name="${prefix}robotiq_85_right_finger_link">
            <visual>
                <geometry>
                    <mesh filename="package://robotiq_85_description/meshes/visual/robotiq_85_finger_link.dae"/>
                </geometry>
            </visual>
            <collision>
                <geometry>
                    <mesh filename="package://robotiq_85_description/meshes/collision/robotiq_85_finger_link.stl"/>
                </geometry>
            </collision>
            <inertial>
              <mass value="0.0000027309" />
              <origin xyz="0.0 0.0 0.0" />
              <inertia ixx = "${0.000003/K}" ixy = "${-0.000002/K}" ixz = "${0.000000/K}"
                       iyx = "${-0.000002/K}" iyy = "${0.000021/K}" iyz = "${0.000000/K}"
                       izx = "${0.000000/K}" izy = "${0.000000/K}" izz = "${0.000020/K}" />
            </inertial>
        </link> 
        <!-- gazebo -->
		<gazebo reference="${prefix}robotiq_85_right_finger_link">
			<implicitSpringDamper>1</implicitSpringDamper>
			<mu1>100000</mu1>
			<mu2>100000</mu2>
			<kp>100000000.0</kp>
			<kd>1.0</kd>
  		</gazebo>
        <joint name="${prefix}robotiq_85_left_inner_knuckle_joint" type="continuous">
            <parent link="${prefix}robotiq_85_base_link"/>
            <child link="${prefix}robotiq_85_left_inner_knuckle_link"/>
            <axis xyz="0 0 1"/>
            <origin xyz="0.03071 0.00635 0" rpy="${pi} 0.0 0.0" />
            <limit lower="-3.14" upper="3.14" velocity="100.0" effort="0.1"/>
            <mimic joint="${prefix}robotiq_85_left_knuckle_joint" offset="0"/>
        </joint>

        <joint name="${prefix}robotiq_85_right_inner_knuckle_joint" type="continuous">
            <parent link="${prefix}robotiq_85_base_link"/>
            <child link="${prefix}robotiq_85_right_inner_knuckle_link"/>
            <axis xyz="0 0 1"/>
            <origin xyz="0.03071 -0.00635 0" rpy="0 0 0"/>
            <limit lower="-3.14" upper="3.14" velocity="100.0" effort="0.1"/>
            <mimic joint="${prefix}robotiq_85_left_knuckle_joint" offset="0"/>
        </joint>

        <link name="${prefix}robotiq_85_left_inner_knuckle_link">
            <visual>
                <geometry>
                    <mesh filename="package://robotiq_85_description/meshes/visual/robotiq_85_inner_knuckle_link.dae"/>
                </geometry>
            </visual>
            <collision>
                <geometry>
                    <mesh filename="package://robotiq_85_description/meshes/collision/robotiq_85_inner_knuckle_link.stl"/>
                </geometry>
            </collision>
            <inertial>
              <mass value="0.0000029951" />
              <origin xyz="0.0 0.0 0.0" />
              <inertia ixx = "${0.000039/K}" ixy = "${0.000000/K}" ixz = "${0.000000/K}"
                       iyx = "${0.000000/K}" iyy = "${0.000005/K}" iyz = "${0.000000/K}"
                       izx = "${0.000000/K}" izy = "${0.000000/K}" izz = "${0.000035/K}" />
              </inertial>
        </link>
        <!-- gazebo -->
		<gazebo reference="${prefix}robotiq_85_left_inner_knuckle_link">
			<implicitSpringDamper>1</implicitSpringDamper>
			<mu1>100000</mu1>
			<mu2>100000</mu2>
			<kp>100000000.0</kp>
			<kd>1.0</kd>
  		</gazebo>
        <link name="${prefix}robotiq_85_right_inner_knuckle_link">
            <visual>
                <geometry>
                    <mesh filename="package://robotiq_85_description/meshes/visual/robotiq_85_inner_knuckle_link.dae"/>
                </geometry>
            </visual>
            <collision>
                <geometry>
                    <mesh filename="package://robotiq_85_description/meshes/collision/robotiq_85_inner_knuckle_link.stl"/>
                </geometry>
            </collision>
            <inertial>
              <mass value="0.0000029951" />
              <origin xyz="0.0 0.0 0.0" />
              <inertia ixx = "${0.000039/K}" ixy = "${0.000000/K}" ixz = "${0.000000/K}"
                       iyx = "${0.000000/K}" iyy = "${0.000005/K}" iyz = "${0.000000/K}"
                       izx = "${0.000000/K}" izy = "${0.000000/K}" izz = "${0.000035/K}" />
            </inertial>
        </link>
        <!-- gazebo -->
		<gazebo reference="${prefix}robotiq_85_right_inner_knuckle_link">
			<implicitSpringDamper>1</implicitSpringDamper>
			<mu1>100000</mu1>
			<mu2>100000</mu2>
			<kp>100000000.0</kp>
			<kd>1.0</kd>
  		</gazebo>
        <joint name="${prefix}robotiq_85_left_finger_tip_joint" type="continuous">
            <parent link="${prefix}robotiq_85_left_inner_knuckle_link"/>
            <child link="${prefix}robotiq_85_left_finger_tip_link"/>
            <axis xyz="0 0 1"/>
            <origin xyz="0.021519799035 -0.018799704105 0.0" rpy="0.0 0.0 0.0"/>
            <limit lower="-3.14" upper="3.14" velocity="100.0" effort="0.1"/>
            <mimic joint="${prefix}robotiq_85_left_knuckle_joint" multiplier="-1"/>
        </joint>

        <joint name="${prefix}robotiq_85_right_finger_tip_joint" type="continuous">
            <parent link="${prefix}robotiq_85_right_inner_knuckle_link"/>
            <child link="${prefix}robotiq_85_right_finger_tip_link"/>
            <axis xyz="0 0 1"/>
            <origin rpy="0.0 0.0 0.0" xyz="0.021519799035 -0.018799704105  0.0"/>
            <limit lower="-3.14" upper="3.14" velocity="100.0" effort="0.1"/>
            <mimic joint="${prefix}robotiq_85_left_knuckle_joint" multiplier="-1"/>
        </joint>


        <link name="${prefix}robotiq_85_left_finger_tip_link">
            <visual>
                <geometry>
                    <mesh filename="package://robotiq_85_description/meshes/visual/robotiq_85_finger_tip_link.dae"/>
                </geometry>
            </visual>
            <collision>
                <geometry>
                    <mesh filename="package://robotiq_85_description/meshes/collision/robotiq_85_finger_tip_link.stl"/>
                </geometry>
            </collision>
            <inertial>
              <mass value="0.0000019555" />
              <origin xyz="0.0 0.0 0.0" />
              <inertia ixx = "${0.000002/K}" ixy = "${0.000000/K}" ixz = "${0.000000/K}"
                       iyx = "${0.000000/K}" iyy = "${0.000005/K}" iyz = "${0.000000/K}"
                       izx = "${0.000000/K}" izy = "${0.000000/K}" izz = "${0.000006/K}" />
              </inertial>
        </link> 

		<!-- gazebo -->
		<gazebo reference="${prefix}robotiq_85_left_finger_tip_link">
			<implicitSpringDamper>1</implicitSpringDamper>
			<mu1>100000</mu1>
			<mu2>100000</mu2>
			<kp>100000000.0</kp>
			<kd>1.0</kd>
  		</gazebo>


        <link name="${prefix}robotiq_85_right_finger_tip_link">
            <visual>
                <geometry>
                    <mesh filename="package://robotiq_85_description/meshes/visual/robotiq_85_finger_tip_link.dae"/>
                </geometry>
            </visual>s
            <collision>
                <geometry>
                    <mesh filename="package://robotiq_85_description/meshes/collision/robotiq_85_finger_tip_link.stl"/>
                </geometry>
            </collision>
            <inertial>
              <mass value="0.0000019555" />
              <origin xyz="0.0 0.0 0.0" />
              <inertia ixx = "${0.000002/K}" ixy = "${0.000000/K}" ixz = "${0.000000/K}"
                       iyx = "${0.000000/K}" iyy = "${0.000005/K}" iyz = "${0.000000/K}"
                       izx = "${0.000000/K}" izy = "${0.000000/K}" izz = "${0.000006/K}" />
            </inertial>
        </link>
        <!-- gazebo -->
		<gazebo reference="${prefix}robotiq_85_right_finger_tip_link">
			<implicitSpringDamper>1</implicitSpringDamper>
			<mu1>100000</mu1>
			<mu2>100000</mu2>
			<kp>100000000.0</kp>
			<kd>1.0</kd>
  		</gazebo>

        <xacro:robotiq_85_gripper_transmission prefix="${prefix}" />

    </xacro:macro>
</robot>
